Traceback (most recent call last):
  File "/Users/mbeckett/Documents/codeprojects/linkedin-automation-api/venv/lib/python3.11/site-packages/sqlalchemy/engine/base.py", line 145, in __init__
    self._dbapi_connection = engine.raw_connection()
                             ^^^^^^^^^^^^^^^^^^^^^^^
  File "/Users/mbeckett/Documents/codeprojects/linkedin-automation-api/venv/lib/python3.11/site-packages/sqlalchemy/engine/base.py", line 3297, in raw_connection
    return self.pool.connect()
           ^^^^^^^^^^^^^^^^^^^
  File "/Users/mbeckett/Documents/codeprojects/linkedin-automation-api/venv/lib/python3.11/site-packages/sqlalchemy/pool/base.py", line 449, in connect
    return _ConnectionFairy._checkout(self)
           ^^^^^^^^^^^^^^^^^^^^^^^^^^^^^^^^
  File "/Users/mbeckett/Documents/codeprojects/linkedin-automation-api/venv/lib/python3.11/site-packages/sqlalchemy/pool/base.py", line 1264, in _checkout
    fairy = _ConnectionRecord.checkout(pool)
            ^^^^^^^^^^^^^^^^^^^^^^^^^^^^^^^^
  File "/Users/mbeckett/Documents/codeprojects/linkedin-automation-api/venv/lib/python3.11/site-packages/sqlalchemy/pool/base.py", line 713, in checkout
    rec = pool._do_get()
          ^^^^^^^^^^^^^^
  File "/Users/mbeckett/Documents/codeprojects/linkedin-automation-api/venv/lib/python3.11/site-packages/sqlalchemy/pool/impl.py", line 179, in _do_get
    with util.safe_reraise():
  File "/Users/mbeckett/Documents/codeprojects/linkedin-automation-api/venv/lib/python3.11/site-packages/sqlalchemy/util/langhelpers.py", line 224, in __exit__
    raise exc_value.with_traceback(exc_tb)
  File "/Users/mbeckett/Documents/codeprojects/linkedin-automation-api/venv/lib/python3.11/site-packages/sqlalchemy/pool/impl.py", line 177, in _do_get
    return self._create_connection()
           ^^^^^^^^^^^^^^^^^^^^^^^^^
  File "/Users/mbeckett/Documents/codeprojects/linkedin-automation-api/venv/lib/python3.11/site-packages/sqlalchemy/pool/base.py", line 390, in _create_connection
    return _ConnectionRecord(self)
           ^^^^^^^^^^^^^^^^^^^^^^^
  File "/Users/mbeckett/Documents/codeprojects/linkedin-automation-api/venv/lib/python3.11/site-packages/sqlalchemy/pool/base.py", line 675, in __init__
    self.__connect()
  File "/Users/mbeckett/Documents/codeprojects/linkedin-automation-api/venv/lib/python3.11/site-packages/sqlalchemy/pool/base.py", line 901, in __connect
    with util.safe_reraise():
  File "/Users/mbeckett/Documents/codeprojects/linkedin-automation-api/venv/lib/python3.11/site-packages/sqlalchemy/util/langhelpers.py", line 224, in __exit__
    raise exc_value.with_traceback(exc_tb)
  File "/Users/mbeckett/Documents/codeprojects/linkedin-automation-api/venv/lib/python3.11/site-packages/sqlalchemy/pool/base.py", line 897, in __connect
    self.dbapi_connection = connection = pool._invoke_creator(self)
                                         ^^^^^^^^^^^^^^^^^^^^^^^^^^
  File "/Users/mbeckett/Documents/codeprojects/linkedin-automation-api/venv/lib/python3.11/site-packages/sqlalchemy/engine/create.py", line 646, in connect
    return dialect.connect(*cargs, **cparams)
           ^^^^^^^^^^^^^^^^^^^^^^^^^^^^^^^^^^
  File "/Users/mbeckett/Documents/codeprojects/linkedin-automation-api/venv/lib/python3.11/site-packages/sqlalchemy/engine/default.py", line 625, in connect
    return self.loaded_dbapi.connect(*cargs, **cparams)  # type: ignore[no-any-return]  # NOQA: E501
           ^^^^^^^^^^^^^^^^^^^^^^^^^^^^^^^^^^^^^^^^^^^^
sqlite3.OperationalError: unable to open database file

The above exception was the direct cause of the following exception:

Traceback (most recent call last):
  File "/Users/mbeckett/Documents/codeprojects/linkedin-automation-api/src/main.py", line 98, in <module>
    app = create_app()
          ^^^^^^^^^^^^
  File "/Users/mbeckett/Documents/codeprojects/linkedin-automation-api/src/main.py", line 63, in create_app
    db.create_all()
  File "/Users/mbeckett/Documents/codeprojects/linkedin-automation-api/venv/lib/python3.11/site-packages/flask_sqlalchemy/extension.py", line 900, in create_all
    self._call_for_binds(bind_key, "create_all")
  File "/Users/mbeckett/Documents/codeprojects/linkedin-automation-api/venv/lib/python3.11/site-packages/flask_sqlalchemy/extension.py", line 881, in _call_for_binds
    getattr(metadata, op_name)(bind=engine)
  File "/Users/mbeckett/Documents/codeprojects/linkedin-automation-api/venv/lib/python3.11/site-packages/sqlalchemy/sql/schema.py", line 5924, in create_all
    bind._run_ddl_visitor(
  File "/Users/mbeckett/Documents/codeprojects/linkedin-automation-api/venv/lib/python3.11/site-packages/sqlalchemy/engine/base.py", line 3247, in _run_ddl_visitor
    with self.begin() as conn:
  File "/Users/mbeckett/miniconda3/lib/python3.11/contextlib.py", line 137, in __enter__
    return next(self.gen)
           ^^^^^^^^^^^^^^
  File "/Users/mbeckett/Documents/codeprojects/linkedin-automation-api/venv/lib/python3.11/site-packages/sqlalchemy/engine/base.py", line 3237, in begin
    with self.connect() as conn:
         ^^^^^^^^^^^^^^
  File "/Users/mbeckett/Documents/codeprojects/linkedin-automation-api/venv/lib/python3.11/site-packages/sqlalchemy/engine/base.py", line 3273, in connect
    return self._connection_cls(self)
           ^^^^^^^^^^^^^^^^^^^^^^^^^^
  File "/Users/mbeckett/Documents/codeprojects/linkedin-automation-api/venv/lib/python3.11/site-packages/sqlalchemy/engine/base.py", line 147, in __init__
    Connection._handle_dbapi_exception_noconnection(
  File "/Users/mbeckett/Documents/codeprojects/linkedin-automation-api/venv/lib/python3.11/site-packages/sqlalchemy/engine/base.py", line 2436, in _handle_dbapi_exception_noconnection
    raise sqlalchemy_exception.with_traceback(exc_info[2]) from e
  File "/Users/mbeckett/Documents/codeprojects/linkedin-automation-api/venv/lib/python3.11/site-packages/sqlalchemy/engine/base.py", line 145, in __init__
    self._dbapi_connection = engine.raw_connection()
                             ^^^^^^^^^^^^^^^^^^^^^^^
  File "/Users/mbeckett/Documents/codeprojects/linkedin-automation-api/venv/lib/python3.11/site-packages/sqlalchemy/engine/base.py", line 3297, in raw_connection
    return self.pool.connect()
           ^^^^^^^^^^^^^^^^^^^
  File "/Users/mbeckett/Documents/codeprojects/linkedin-automation-api/venv/lib/python3.11/site-packages/sqlalchemy/pool/base.py", line 449, in connect
    return _ConnectionFairy._checkout(self)
           ^^^^^^^^^^^^^^^^^^^^^^^^^^^^^^^^
  File "/Users/mbeckett/Documents/codeprojects/linkedin-automation-api/venv/lib/python3.11/site-packages/sqlalchemy/pool/base.py", line 1264, in _checkout
    fairy = _ConnectionRecord.checkout(pool)
            ^^^^^^^^^^^^^^^^^^^^^^^^^^^^^^^^
  File "/Users/mbeckett/Documents/codeprojects/linkedin-automation-api/venv/lib/python3.11/site-packages/sqlalchemy/pool/base.py", line 713, in checkout
    rec = pool._do_get()
          ^^^^^^^^^^^^^^
  File "/Users/mbeckett/Documents/codeprojects/linkedin-automation-api/venv/lib/python3.11/site-packages/sqlalchemy/pool/impl.py", line 179, in _do_get
    with util.safe_reraise():
  File "/Users/mbeckett/Documents/codeprojects/linkedin-automation-api/venv/lib/python3.11/site-packages/sqlalchemy/util/langhelpers.py", line 224, in __exit__
    raise exc_value.with_traceback(exc_tb)
  File "/Users/mbeckett/Documents/codeprojects/linkedin-automation-api/venv/lib/python3.11/site-packages/sqlalchemy/pool/impl.py", line 177, in _do_get
    return self._create_connection()
           ^^^^^^^^^^^^^^^^^^^^^^^^^
  File "/Users/mbeckett/Documents/codeprojects/linkedin-automation-api/venv/lib/python3.11/site-packages/sqlalchemy/pool/base.py", line 390, in _create_connection
    return _ConnectionRecord(self)
           ^^^^^^^^^^^^^^^^^^^^^^^
  File "/Users/mbeckett/Documents/codeprojects/linkedin-automation-api/venv/lib/python3.11/site-packages/sqlalchemy/pool/base.py", line 675, in __init__
    self.__connect()
  File "/Users/mbeckett/Documents/codeprojects/linkedin-automation-api/venv/lib/python3.11/site-packages/sqlalchemy/pool/base.py", line 901, in __connect
    with util.safe_reraise():
  File "/Users/mbeckett/Documents/codeprojects/linkedin-automation-api/venv/lib/python3.11/site-packages/sqlalchemy/util/langhelpers.py", line 224, in __exit__
    raise exc_value.with_traceback(exc_tb)
  File "/Users/mbeckett/Documents/codeprojects/linkedin-automation-api/venv/lib/python3.11/site-packages/sqlalchemy/pool/base.py", line 897, in __connect
    self.dbapi_connection = connection = pool._invoke_creator(self)
                                         ^^^^^^^^^^^^^^^^^^^^^^^^^^
  File "/Users/mbeckett/Documents/codeprojects/linkedin-automation-api/venv/lib/python3.11/site-packages/sqlalchemy/engine/create.py", line 646, in connect
    return dialect.connect(*cargs, **cparams)
           ^^^^^^^^^^^^^^^^^^^^^^^^^^^^^^^^^^
  File "/Users/mbeckett/Documents/codeprojects/linkedin-automation-api/venv/lib/python3.11/site-packages/sqlalchemy/engine/default.py", line 625, in connect
    return self.loaded_dbapi.connect(*cargs, **cparams)  # type: ignore[no-any-return]  # NOQA: E501
           ^^^^^^^^^^^^^^^^^^^^^^^^^^^^^^^^^^^^^^^^^^^^
sqlalchemy.exc.OperationalError: (sqlite3.OperationalError) unable to open database file
(Background on this error at: https://sqlalche.me/e/20/e3q8)
